Workbook

Sheet Récap
A1: Tacos Fox : carte relevée sur la borne
A2: Relevé fait à partir de photos de la borne de commande et des écrans muraux, octobre 2026. À faire valider par le restaurant.
A4: Enseigne | B4: TACOSFOX by Paris, since 1998
A5: Adresse | B5: 210 Avenue du 8 Mai 1945, 93150 Le Blanc-Mesnil (à confirmer)
A6: Slogan | B6: La meilleure excuse pour ne pas cuisiner ce soir
A7: Certification | B7: Viande halal contrôlée Achahada
A8: Offre phare | B8: 1 pizza achetée = 1 pizza offerte (Senior et Mega)
A10: Catégorie | B10: Nb de lignes | C10: Dont à vérifier
A11: Crousty Fox | B11: =COUNTIF(Carte!$A$2:$A$134,A11) -> 4 | C11: =COUNTIFS(Carte!$A$2:$A$134,A11,Carte!$G$2:$G$134,"À vérifier") -> 0
A12: Assiette | B12: =COUNTIF(Carte!$A$2:$A$134,A12) -> 5 | C12: =COUNTIFS(Carte!$A$2:$A$134,A12,Carte!$G$2:$G$134,"À vérifier") -> 0
A13: Sandwich | B13: =COUNTIF(Carte!$A$2:$A$134,A13) -> 34 | C13: =COUNTIFS(Carte!$A$2:$A$134,A13,Carte!$G$2:$G$134,"À vérifier") -> 2
A14: Burger | B14: =COUNTIF(Carte!$A$2:$A$134,A14) -> 20 | C14: =COUNTIFS(Carte!$A$2:$A$134,A14,Carte!$G$2:$G$134,"À vérifier") -> 0
A15: Bowl | B15: =COUNTIF(Carte!$A$2:$A$134,A15) -> 2 | C15: =COUNTIFS(Carte!$A$2:$A$134,A15,Carte!$G$2:$G$134,"À vérifier") -> 0
A16: Tacos | B16: =COUNTIF(Carte!$A$2:$A$134,A16) -> 5 | C16: =COUNTIFS(Carte!$A$2:$A$134,A16,Carte!$G$2:$G$134,"À vérifier") -> 0
A17: Pizza | B17: =COUNTIF(Carte!$A$2:$A$134,A17) -> 41 | C17: =COUNTIFS(Carte!$A$2:$A$134,A17,Carte!$G$2:$G$134,"À vérifier") -> 4
A18: Panini | B18: =COUNTIF(Carte!$A$2:$A$134,A18) -> 2 | C18: =COUNTIFS(Carte!$A$2:$A$134,A18,Carte!$G$2:$G$134,"À vérifier") -> 2
A19: Pâtes | B19: =COUNTIF(Carte!$A$2:$A$134,A19) -> 2 | C19: =COUNTIFS(Carte!$A$2:$A$134,A19,Carte!$G$2:$G$134,"À vérifier") -> 0
A20: Salade | B20: =COUNTIF(Carte!$A$2:$A$134,A20) -> 5 | C20: =COUNTIFS(Carte!$A$2:$A$134,A20,Carte!$G$2:$G$134,"À vérifier") -> 1
A21: Crêpe | B21: =COUNTIF(Carte!$A$2:$A$134,A21) -> 2 | C21: =COUNTIFS(Carte!$A$2:$A$134,A21,Carte!$G$2:$G$134,"À vérifier") -> 2
A22: Milkshake | B22: =COUNTIF(Carte!$A$2:$A$134,A22) -> 1 | C22: =COUNTIFS(Carte!$A$2:$A$134,A22,Carte!$G$2:$G$134,"À vérifier") -> 0
... A27: Boissons | B27: =COUNTIF(Carte!$A$2:$A$134,A27) -> 1 | C27: =COUNTIFS(Carte!$A$2:$A$134,A27,Carte!$G$2:$G$134,"À vérifier") -> 1
A28: Total | B28: =SUM(B11:B27) -> 133 | C28: =SUM(C11:C27) -> 15
A30: Légende
A31: Ligne surlignée en jaune | B31: Information manquante ou illisible, à demander au restaurant

Sheet Carte
A1: Catégorie | B1: Gamme | C1: Produit | D1: Composition | E1: Prix (€) | F1: Formule | G1: Statut | H1: Note
A2: Crousty Fox | C2: Crousty Fox Menu | E2: 10 | F2: Boisson incluse | G2: OK
A3: Crousty Fox | C3: Crousty Fox sauce fromage | E3: 9 | F3: Seul | G3: OK
A4: Crousty Fox | C4: Crousty Fox spicy sucré | E4: 9 | F4: Seul | G4: OK
A5: Crousty Fox | C5: Crousty Fox sucré | E5: 9 | F5: Seul | G5: OK
A6: Assiette | C6: Kebab | D6: Salade, tomate, oignon, frites | E6: 13.9 | F6: Boisson incluse | G6: OK
A7: Assiette | C7: Chicken | D7: Salade, tomate, oignon, frites | E7: 13.9 | F7: Boisson incluse | G7: OK
A8: Assiette | C8: Mixte | D8: Salade, tomate, oignon, frites | E8: 15.7 | F8: Boisson incluse | G8: OK
A9: Assiette | C9: Chicken rouge | D9: Salade, tomate, oignon, frites | E9: 13.9 | F9: Boisson incluse | G9: OK
A10: Assiette | C10: Escalope | D10: Salade, tomate, oignon, frites | E10: 13.9 | F10: Boisson incluse | G10: OK
A11: Sandwich | C11: Grec | D11: Kebab, crudités au choix | E11: 9.7 | F11: Menu (frites + boisson) | G11: OK
A12: Sandwich | C12: Mixte | D12: 2 viandes au choix, fromage, crudités au choix | E12: 10.3 | F12: Menu (frites + boisson) | G12: OK
A13: Sandwich | C13: Spécial Fox | D13: Viande au choix, chèvre, fromage, miel, crudités au choix | E13: 11.5 | F13: Menu (frites + boisson) | G13: OK
A14: Sandwich | C14: Spécial | D14: Chicken rouge, poivron, olive, oignon frit, 2 fromages, crudités au choix | E14: 9.9 | F14: Menu (frites + boisson) | G14: OK
A15: Sandwich | B15: Les essentiels | C15: Steak | D15: 2 steaks, fromage, crudités au choix | E15: 8.8 | F15: Menu (frites + boisson) | G15: OK
A16: Sandwich | B16: Les essentiels | C16: Merguez | D16: Merguez, fromage | E16: 8.9 | F16: Menu (frites + boisson) | G16: OK
A17: Sandwich | B17: Les essentiels | C17: Escalope | D17: Escalope de poulet, fromage, crudités au choix | E17: 9.5 | F17: Menu (frites + boisson) | G17: OK
A18: Sandwich | B18: Les essentiels | C18: Chicken jaune | D18: Chicken, fromage | E18: 9.8 | F18: Menu (frites + boisson) | G18: OK
A19: Sandwich | C19: Chicken rouge | D19: Chicken rouge | E19: 9.8 | F19: Menu (frites + boisson) | G19: OK
A20: Sandwich | B20: Les premiums | C20: Mortel | D20: Viande au choix, œuf, boursin, jambon de dinde, fromage, crudités au choix | E20: 11.6 | F20: Menu (frites + boisson) | G20: OK
A21: Sandwich | B21: Les premiums | C21: Seven | D21: 3 steaks, fromage, chicken, escalope, crudités au choix | E21: 11.9 | F21: Menu (frites + boisson) | G21: OK
A22: Sandwich | B22: Les premiums | C22: Tentation | D22: 2 steaks, œuf, fromage, crudités au choix | E22: 9.3 | F22: Menu (frites + boisson) | G22: OK
A23: Sandwich | B23: Les premiums | C23: Magistral | D23: Galette de pomme de terre, escalope, fromage, crudités au choix | E23: 9.9 | F23: Menu (frites + boisson) | G23: OK
A24: Sandwich | B24: Les premiums | C24: Radical | D24: Chicken rouge, cordon bleu, crudités au choix | E24: 10 | F24: Menu (frites + boisson) | G24: OK
A25: Sandwich | B25: Les premiums | C25: Mexicain | D25: 2 steaks, poivrons, œuf, 2 fromages, crudités au choix | E25: 9.5 | F25: Menu (frites + boisson) | G25: OK
A26: Sandwich | B26: Les premiums | C26: Royal Fox | D26: Escalope, cordon bleu, fromage | E26: 10 | F26: Menu (frites + boisson) | G26: OK
A27: Sandwich | B27: Les premiums | C27: Magic | D27: 2 steaks, cordon bleu, fromage, crudités au choix | E27: 10.2 | F27: Menu (frites + boisson) | G27: OK
A28: Sandwich | B28: Les premiums | C28: Triple X | D28: 3 steaks, œuf, fromage, crudités au choix | E28: 10.2 | F28: Menu (frites + boisson) | G28: OK
A29: Sandwich | B29: Les premiums | C29: X Trem | D29: 2 steaks, œuf, jambon de dinde, fromage, crudités au choix | E29: 10.1 | F29: Menu (frites + boisson) | G29: OK
A30: Sandwich | B30: Les premiums | C30: Savoyard | D30: Chicken blanc, lardon, chèvre, crudités au choix | E30: 10.2 | F30: Menu (frites + boisson) | G30: OK
A31: Sandwich | B31: Les premiums | C31: Charcutier | D31: Chicken au choix, chorizo, emmental, crudités au choix | E31: 10.5 | F31: Menu (frites + boisson) | G31: OK
... A33: Sandwich | B33: Les premiums | C33: Fabuleux | D33: Viande au choix, chorizo, emmental, jambon de dinde, poulet, crudités au choix | E33: 10.4 | F33: Menu (frites + boisson) | G33: OK
A34: Sandwich | C34: Suprême | D34: 2 steaks, escalope, galette de pomme de terre, emmental, crudités au choix | E34: 10.9 | F34: Menu (frites + boisson) | G34: OK
A35: Sandwich | C35: Buffalo | D35: 2 steaks, œuf, jambon de dinde, escalope, fromage, crudités au choix | E35: 11.2 | F35: Menu (frites + boisson) | G35: OK
A36: Sandwich | C36: Blindé | D36: 2 steaks, grec, cordon bleu, escalope, fromage, crudités au choix | E36: 11.3 | F36: Menu (frites + boisson) | G36: OK
A37: Sandwich | C37: Monster Fox | D37: 2 steaks, grec, cordon bleu, fromage, oignon | E37: 11.5 | F37: Menu (frites + boisson) | G37: OK
A38: Sandwich | C38: Five Fox | D38: 5 steaks, 5 fromages, crudités au choix | E38: 11.6 | F38: Menu (frites + boisson) | G38: OK
A39: Sandwich | C39: Escalope du Chef | D39: Champignon, crème fraîche, œuf, fromage | E39: 10.2 | F39: Menu (frites + boisson) | G39: OK
A40: Sandwich | C40: Tenders au four | D40: Tenders, mozzarella, boursin, crudités au choix | E40: 10 | F40: Menu (frites + boisson) | G40: OK
A41: Sandwich | C41: Spécial au four | D41: Viande au choix, mozza, crudités au choix | E41: 10.3 | F41: Menu (frites + boisson) | G41: OK
...

Sheet Options
A1: Type d'option | B1: Choix | C1: Supplément (€) | D1: Note
A2: Viandes tacos (2 minimum en L) | B2: Chicken jaune
A3: Viandes tacos (2 minimum en L) | B3: Chicken rouge
A4: Viandes tacos (2 minimum en L) | B4: Cordon bleu
A5: Viandes tacos (2 minimum en L) | B5: Escalope
A6: Viandes tacos (2 minimum en L) | B6: Kebab
A7: Viandes tacos (2 minimum en L) | B7: Merguez
A8: Viandes tacos (2 minimum en L) | B8: Nuggets
A9: Viandes tacos (2 minimum en L) | B9: Tenders
A10: Viandes tacos (2 minimum en L) | B10: Viande hachée
A11: Viande panini (1 choix) | B11: Chicken jaune
A12: Viande panini (1 choix) | B12: Chicken rouge
A13: Viande panini (1 choix) | B13: Escalope
... A22: Viande panini (1 choix) | B22: Viande hachée
A23: Sauces (2 maximum) | B23: Algérienne | D23: Incluse
A24: Sauces (2 maximum) | B24: Andalouse | D24: Incluse
A25: Sauces (2 maximum) | B25: Barbecue | D25: Incluse
A26: Sauces (2 maximum) | B26: Biggy | D26: Incluse
A27: Sauces (2 maximum) | B27: Cheezy | D27: Incluse
A28: Sauces (2 maximum) | B28: Chili thaï | D28: Incluse
A29: Sauces (2 maximum) | B29: Curry | D29: Incluse
A30: Sauces (2 maximum) | B30: Fish | D30: Incluse
A31: Sauces (2 maximum) | B31: Harissa | D31: Incluse
A32: Sauces (2 maximum) | B32: Ketchup | D32: Incluse
A33: Sauces (2 maximum) | B33: Mayonnaise | D33: Incluse
A34: Sauces (2 maximum) | B34: Poivre | D34: Incluse
... A37: Sauces (2 maximum) | B37: Yopie | D37: Incluse
A38: Supplément viande | B38: Chorizo | C38: 1.8
A39: Supplément viande | B39: Cordon bleu | C39: 1.8
A40: Supplément viande | B40: Dinde | C40: 1.8
A41: Supplément viande | B41: Escalope | C41: 1.8
A42: Supplément viande | B42: Escalope curry | C42: 1.8
A43: Supplément viande | B43: Escalope tandoori | C43: 1.8
A44: Supplément viande | B44: Kebab | C44: 1.8
A45: Supplément viande | B45: Lardon | C45: 1.8
A46: Supplément viande | B46: Merguez | C46: 1.8
A47: Supplément viande | B47: Nuggets | C47: 1.8
A48: Supplément viande | B48: Saumon | C48: 2.5
A49: Supplément viande | B49: Tenders | C49: 1.5
... A59: Supplément fromage | B59: Mozzarella | C59: 0.7
...
